[2022-11-26T00:08:14.992+0000] {taskinstance.py:1165} INFO - Dependencies all met for <TaskInstance: data_generator_dag.data_generation scheduled__2022-11-25T00:00:00+00:00 [queued]>
[2022-11-26T00:08:15.013+0000] {taskinstance.py:1165} INFO - Dependencies all met for <TaskInstance: data_generator_dag.data_generation scheduled__2022-11-25T00:00:00+00:00 [queued]>
[2022-11-26T00:08:15.017+0000] {taskinstance.py:1362} INFO - 
--------------------------------------------------------------------------------
[2022-11-26T00:08:15.020+0000] {taskinstance.py:1363} INFO - Starting attempt 1 of 1
[2022-11-26T00:08:15.021+0000] {taskinstance.py:1364} INFO - 
--------------------------------------------------------------------------------
[2022-11-26T00:08:15.055+0000] {taskinstance.py:1383} INFO - Executing <Task(PythonOperator): data_generation> on 2022-11-25 00:00:00+00:00
[2022-11-26T00:08:15.102+0000] {standard_task_runner.py:55} INFO - Started process 2715 to run task
[2022-11-26T00:08:15.132+0000] {standard_task_runner.py:82} INFO - Running: ['***', 'tasks', 'run', 'data_generator_dag', 'data_generation', 'scheduled__2022-11-25T00:00:00+00:00', '--job-id', '275', '--raw', '--subdir', 'DAGS_FOLDER/dag_generate_data.py', '--cfg-path', '/tmp/tmp701jweay']
[2022-11-26T00:08:15.142+0000] {standard_task_runner.py:83} INFO - Job 275: Subtask data_generation
[2022-11-26T00:08:15.460+0000] {task_command.py:376} INFO - Running <TaskInstance: data_generator_dag.data_generation scheduled__2022-11-25T00:00:00+00:00 [running]> on host 1b5d66f3d148
[2022-11-26T00:08:15.698+0000] {taskinstance.py:1592} INFO - Exporting the following env vars:
AIRFLOW_CTX_DAG_OWNER=***
AIRFLOW_CTX_DAG_ID=data_generator_dag
AIRFLOW_CTX_TASK_ID=data_generation
AIRFLOW_CTX_EXECUTION_DATE=2022-11-25T00:00:00+00:00
AIRFLOW_CTX_TRY_NUMBER=1
AIRFLOW_CTX_DAG_RUN_ID=scheduled__2022-11-25T00:00:00+00:00
[2022-11-26T00:08:15.743+0000] {taskinstance.py:1851} ERROR - Task failed with exception
Traceback (most recent call last):
  File "/home/airflow/.local/lib/python3.7/site-packages/airflow/operators/python.py", line 175, in execute
    return_value = self.execute_callable()
  File "/home/airflow/.local/lib/python3.7/site-packages/airflow/operators/python.py", line 193, in execute_callable
    return self.python_callable(*self.op_args, **self.op_kwargs)
  File "/opt/airflow/dags/packages/gen2_data.py", line 6, in gen_data
    df = pd.read_csv('../../../data/data.csv')
  File "/home/airflow/.local/lib/python3.7/site-packages/pandas/util/_decorators.py", line 311, in wrapper
    return func(*args, **kwargs)
  File "/home/airflow/.local/lib/python3.7/site-packages/pandas/io/parsers/readers.py", line 586, in read_csv
    return _read(filepath_or_buffer, kwds)
  File "/home/airflow/.local/lib/python3.7/site-packages/pandas/io/parsers/readers.py", line 482, in _read
    parser = TextFileReader(filepath_or_buffer, **kwds)
  File "/home/airflow/.local/lib/python3.7/site-packages/pandas/io/parsers/readers.py", line 811, in __init__
    self._engine = self._make_engine(self.engine)
  File "/home/airflow/.local/lib/python3.7/site-packages/pandas/io/parsers/readers.py", line 1040, in _make_engine
    return mapping[engine](self.f, **self.options)  # type: ignore[call-arg]
  File "/home/airflow/.local/lib/python3.7/site-packages/pandas/io/parsers/c_parser_wrapper.py", line 51, in __init__
    self._open_handles(src, kwds)
  File "/home/airflow/.local/lib/python3.7/site-packages/pandas/io/parsers/base_parser.py", line 229, in _open_handles
    errors=kwds.get("encoding_errors", "strict"),
  File "/home/airflow/.local/lib/python3.7/site-packages/pandas/io/common.py", line 707, in get_handle
    newline="",
FileNotFoundError: [Errno 2] No such file or directory: '../../../data/data.csv'
[2022-11-26T00:08:15.839+0000] {taskinstance.py:1406} INFO - Marking task as FAILED. dag_id=data_generator_dag, task_id=data_generation, execution_date=20221125T000000, start_date=20221126T000814, end_date=20221126T000815
[2022-11-26T00:08:15.911+0000] {standard_task_runner.py:105} ERROR - Failed to execute job 275 for task data_generation ([Errno 2] No such file or directory: '../../../data/data.csv'; 2715)
[2022-11-26T00:08:16.145+0000] {local_task_job.py:159} INFO - Task exited with return code 1
[2022-11-26T00:08:16.504+0000] {taskinstance.py:2623} INFO - 0 downstream tasks scheduled from follow-on schedule check
[2022-11-26T15:18:59.399+0000] {taskinstance.py:1165} INFO - Dependencies all met for <TaskInstance: data_generator_dag.data_generation scheduled__2022-11-25T00:00:00+00:00 [queued]>
[2022-11-26T15:18:59.428+0000] {taskinstance.py:1165} INFO - Dependencies all met for <TaskInstance: data_generator_dag.data_generation scheduled__2022-11-25T00:00:00+00:00 [queued]>
[2022-11-26T15:18:59.433+0000] {taskinstance.py:1362} INFO - 
--------------------------------------------------------------------------------
[2022-11-26T15:18:59.434+0000] {taskinstance.py:1363} INFO - Starting attempt 1 of 1
[2022-11-26T15:18:59.436+0000] {taskinstance.py:1364} INFO - 
--------------------------------------------------------------------------------
[2022-11-26T15:18:59.458+0000] {taskinstance.py:1383} INFO - Executing <Task(PythonOperator): data_generation> on 2022-11-25 00:00:00+00:00
[2022-11-26T15:18:59.479+0000] {standard_task_runner.py:55} INFO - Started process 74 to run task
[2022-11-26T15:18:59.501+0000] {standard_task_runner.py:82} INFO - Running: ['***', 'tasks', 'run', 'data_generator_dag', 'data_generation', 'scheduled__2022-11-25T00:00:00+00:00', '--job-id', '3', '--raw', '--subdir', 'DAGS_FOLDER/dag_generate_data.py', '--cfg-path', '/tmp/tmpz57b3rkg']
[2022-11-26T15:18:59.510+0000] {standard_task_runner.py:83} INFO - Job 3: Subtask data_generation
[2022-11-26T15:18:59.773+0000] {task_command.py:376} INFO - Running <TaskInstance: data_generator_dag.data_generation scheduled__2022-11-25T00:00:00+00:00 [running]> on host 18e45f209dfb
[2022-11-26T15:18:59.856+0000] {taskinstance.py:1592} INFO - Exporting the following env vars:
AIRFLOW_CTX_DAG_OWNER=***
AIRFLOW_CTX_DAG_ID=data_generator_dag
AIRFLOW_CTX_TASK_ID=data_generation
AIRFLOW_CTX_EXECUTION_DATE=2022-11-25T00:00:00+00:00
AIRFLOW_CTX_TRY_NUMBER=1
AIRFLOW_CTX_DAG_RUN_ID=scheduled__2022-11-25T00:00:00+00:00
[2022-11-26T15:18:59.859+0000] {logging_mixin.py:137} INFO - current spot /opt/***
[2022-11-26T15:18:59.860+0000] {logging_mixin.py:137} INFO - current files ['dags', 'logs', '***-worker.pid', 'plugins', '***.cfg', 'webserver_config.py']
[2022-11-26T15:18:59.958+0000] {python.py:177} INFO - Done. Returned value was: None
[2022-11-26T15:18:59.972+0000] {taskinstance.py:1406} INFO - Marking task as SUCCESS. dag_id=data_generator_dag, task_id=data_generation, execution_date=20221125T000000, start_date=20221126T151859, end_date=20221126T151859
[2022-11-26T15:19:00.043+0000] {local_task_job.py:159} INFO - Task exited with return code 0
[2022-11-26T15:19:00.080+0000] {taskinstance.py:2623} INFO - 0 downstream tasks scheduled from follow-on schedule check
