[2022-11-26T08:03:09.051+0000] {taskinstance.py:1165} INFO - Dependencies all met for <TaskInstance: data_generator_dag.data_generation manual__2022-11-26T07:59:56.854823+00:00 [queued]>
[2022-11-26T08:03:09.058+0000] {taskinstance.py:1165} INFO - Dependencies all met for <TaskInstance: data_generator_dag.data_generation manual__2022-11-26T07:59:56.854823+00:00 [queued]>
[2022-11-26T08:03:09.059+0000] {taskinstance.py:1362} INFO - 
--------------------------------------------------------------------------------
[2022-11-26T08:03:09.059+0000] {taskinstance.py:1363} INFO - Starting attempt 3 of 3
[2022-11-26T08:03:09.060+0000] {taskinstance.py:1364} INFO - 
--------------------------------------------------------------------------------
[2022-11-26T08:03:09.068+0000] {taskinstance.py:1383} INFO - Executing <Task(PythonOperator): data_generation> on 2022-11-26 07:59:56.854823+00:00
[2022-11-26T08:03:09.074+0000] {standard_task_runner.py:55} INFO - Started process 246 to run task
[2022-11-26T08:03:09.078+0000] {standard_task_runner.py:82} INFO - Running: ['***', 'tasks', 'run', 'data_generator_dag', 'data_generation', 'manual__2022-11-26T07:59:56.854823+00:00', '--job-id', '467', '--raw', '--subdir', 'DAGS_FOLDER/dag_generate_data.py', '--cfg-path', '/tmp/tmpaifwr9kx']
[2022-11-26T08:03:09.081+0000] {standard_task_runner.py:83} INFO - Job 467: Subtask data_generation
[2022-11-26T08:03:09.144+0000] {task_command.py:376} INFO - Running <TaskInstance: data_generator_dag.data_generation manual__2022-11-26T07:59:56.854823+00:00 [running]> on host 3151441c8efc
[2022-11-26T08:03:09.194+0000] {taskinstance.py:1592} INFO - Exporting the following env vars:
AIRFLOW_CTX_DAG_OWNER=***
AIRFLOW_CTX_DAG_ID=data_generator_dag
AIRFLOW_CTX_TASK_ID=data_generation
AIRFLOW_CTX_EXECUTION_DATE=2022-11-26T07:59:56.854823+00:00
AIRFLOW_CTX_TRY_NUMBER=3
AIRFLOW_CTX_DAG_RUN_ID=manual__2022-11-26T07:59:56.854823+00:00
[2022-11-26T08:03:09.196+0000] {logging_mixin.py:137} INFO - current spot /opt/***
[2022-11-26T08:03:09.197+0000] {logging_mixin.py:137} INFO - current files ['dags', 'logs', '***-worker.pid', 'plugins', '***.cfg', 'webserver_config.py']
[2022-11-26T08:03:09.198+0000] {taskinstance.py:1851} ERROR - Task failed with exception
Traceback (most recent call last):
  File "/home/airflow/.local/lib/python3.7/site-packages/airflow/operators/python.py", line 175, in execute
    return_value = self.execute_callable()
  File "/home/airflow/.local/lib/python3.7/site-packages/airflow/operators/python.py", line 193, in execute_callable
    return self.python_callable(*self.op_args, **self.op_kwargs)
  File "/opt/airflow/dags/packages/gen2_data.py", line 10, in gen_data
    df = pd.read_csv('./data/raw/ds/data.csv')
  File "/home/airflow/.local/lib/python3.7/site-packages/pandas/util/_decorators.py", line 311, in wrapper
    return func(*args, **kwargs)
  File "/home/airflow/.local/lib/python3.7/site-packages/pandas/io/parsers/readers.py", line 586, in read_csv
    return _read(filepath_or_buffer, kwds)
  File "/home/airflow/.local/lib/python3.7/site-packages/pandas/io/parsers/readers.py", line 482, in _read
    parser = TextFileReader(filepath_or_buffer, **kwds)
  File "/home/airflow/.local/lib/python3.7/site-packages/pandas/io/parsers/readers.py", line 811, in __init__
    self._engine = self._make_engine(self.engine)
  File "/home/airflow/.local/lib/python3.7/site-packages/pandas/io/parsers/readers.py", line 1040, in _make_engine
    return mapping[engine](self.f, **self.options)  # type: ignore[call-arg]
  File "/home/airflow/.local/lib/python3.7/site-packages/pandas/io/parsers/c_parser_wrapper.py", line 51, in __init__
    self._open_handles(src, kwds)
  File "/home/airflow/.local/lib/python3.7/site-packages/pandas/io/parsers/base_parser.py", line 229, in _open_handles
    errors=kwds.get("encoding_errors", "strict"),
  File "/home/airflow/.local/lib/python3.7/site-packages/pandas/io/common.py", line 707, in get_handle
    newline="",
FileNotFoundError: [Errno 2] No such file or directory: './data/raw/ds/data.csv'
[2022-11-26T08:03:09.207+0000] {taskinstance.py:1406} INFO - Marking task as FAILED. dag_id=data_generator_dag, task_id=data_generation, execution_date=20221126T075956, start_date=20221126T080309, end_date=20221126T080309
[2022-11-26T08:03:09.215+0000] {standard_task_runner.py:105} ERROR - Failed to execute job 467 for task data_generation ([Errno 2] No such file or directory: './data/raw/ds/data.csv'; 246)
[2022-11-26T08:03:09.251+0000] {local_task_job.py:159} INFO - Task exited with return code 1
[2022-11-26T08:03:09.267+0000] {taskinstance.py:2623} INFO - 0 downstream tasks scheduled from follow-on schedule check
