[2022-11-26T00:08:18.455+0000] {taskinstance.py:1165} INFO - Dependencies all met for <TaskInstance: data_predict_dag.data_predict scheduled__2022-11-25T00:00:00+00:00 [queued]>
[2022-11-26T00:08:18.462+0000] {taskinstance.py:1165} INFO - Dependencies all met for <TaskInstance: data_predict_dag.data_predict scheduled__2022-11-25T00:00:00+00:00 [queued]>
[2022-11-26T00:08:18.463+0000] {taskinstance.py:1362} INFO - 
--------------------------------------------------------------------------------
[2022-11-26T00:08:18.463+0000] {taskinstance.py:1363} INFO - Starting attempt 1 of 1
[2022-11-26T00:08:18.463+0000] {taskinstance.py:1364} INFO - 
--------------------------------------------------------------------------------
[2022-11-26T00:08:18.477+0000] {taskinstance.py:1383} INFO - Executing <Task(PythonOperator): data_predict> on 2022-11-25 00:00:00+00:00
[2022-11-26T00:08:18.491+0000] {standard_task_runner.py:55} INFO - Started process 2720 to run task
[2022-11-26T00:08:18.497+0000] {standard_task_runner.py:82} INFO - Running: ['***', 'tasks', 'run', 'data_predict_dag', 'data_predict', 'scheduled__2022-11-25T00:00:00+00:00', '--job-id', '276', '--raw', '--subdir', 'DAGS_FOLDER/dag_predict_proccess.py', '--cfg-path', '/tmp/tmpd_voglry']
[2022-11-26T00:08:18.500+0000] {standard_task_runner.py:83} INFO - Job 276: Subtask data_predict
[2022-11-26T00:08:18.574+0000] {task_command.py:376} INFO - Running <TaskInstance: data_predict_dag.data_predict scheduled__2022-11-25T00:00:00+00:00 [running]> on host 1b5d66f3d148
[2022-11-26T00:08:18.676+0000] {taskinstance.py:1592} INFO - Exporting the following env vars:
AIRFLOW_CTX_DAG_OWNER=***
AIRFLOW_CTX_DAG_ID=data_predict_dag
AIRFLOW_CTX_TASK_ID=data_predict
AIRFLOW_CTX_EXECUTION_DATE=2022-11-25T00:00:00+00:00
AIRFLOW_CTX_TRY_NUMBER=1
AIRFLOW_CTX_DAG_RUN_ID=scheduled__2022-11-25T00:00:00+00:00
[2022-11-26T00:08:18.751+0000] {local_task_job.py:159} INFO - Task exited with return code 1
[2022-11-26T00:08:18.770+0000] {taskinstance.py:2623} INFO - 0 downstream tasks scheduled from follow-on schedule check
[2022-11-26T15:19:01.869+0000] {taskinstance.py:1165} INFO - Dependencies all met for <TaskInstance: data_predict_dag.data_predict scheduled__2022-11-25T00:00:00+00:00 [queued]>
[2022-11-26T15:19:01.883+0000] {taskinstance.py:1165} INFO - Dependencies all met for <TaskInstance: data_predict_dag.data_predict scheduled__2022-11-25T00:00:00+00:00 [queued]>
[2022-11-26T15:19:01.885+0000] {taskinstance.py:1362} INFO - 
--------------------------------------------------------------------------------
[2022-11-26T15:19:01.887+0000] {taskinstance.py:1363} INFO - Starting attempt 1 of 1
[2022-11-26T15:19:01.890+0000] {taskinstance.py:1364} INFO - 
--------------------------------------------------------------------------------
[2022-11-26T15:19:01.916+0000] {taskinstance.py:1383} INFO - Executing <Task(PythonOperator): data_predict> on 2022-11-25 00:00:00+00:00
[2022-11-26T15:19:01.931+0000] {standard_task_runner.py:55} INFO - Started process 78 to run task
[2022-11-26T15:19:01.938+0000] {standard_task_runner.py:82} INFO - Running: ['***', 'tasks', 'run', 'data_predict_dag', 'data_predict', 'scheduled__2022-11-25T00:00:00+00:00', '--job-id', '4', '--raw', '--subdir', 'DAGS_FOLDER/dag_predict_proccess.py', '--cfg-path', '/tmp/tmpjjrchv7w']
[2022-11-26T15:19:01.942+0000] {standard_task_runner.py:83} INFO - Job 4: Subtask data_predict
[2022-11-26T15:19:02.049+0000] {task_command.py:376} INFO - Running <TaskInstance: data_predict_dag.data_predict scheduled__2022-11-25T00:00:00+00:00 [running]> on host 18e45f209dfb
[2022-11-26T15:19:02.119+0000] {taskinstance.py:1592} INFO - Exporting the following env vars:
AIRFLOW_CTX_DAG_OWNER=***
AIRFLOW_CTX_DAG_ID=data_predict_dag
AIRFLOW_CTX_TASK_ID=data_predict
AIRFLOW_CTX_EXECUTION_DATE=2022-11-25T00:00:00+00:00
AIRFLOW_CTX_TRY_NUMBER=1
AIRFLOW_CTX_DAG_RUN_ID=scheduled__2022-11-25T00:00:00+00:00
[2022-11-26T15:19:02.306+0000] {warnings.py:110} WARNING - /home/***/.local/lib/python3.7/site-packages/sklearn/base.py:338: UserWarning: Trying to unpickle estimator MinMaxScaler from version 1.1.3 when using version 1.0.2. This might lead to breaking code or invalid results. Use at your own risk. For more info please refer to:
https://scikit-learn.org/stable/modules/model_persistence.html#security-maintainability-limitations
  UserWarning,

[2022-11-26T15:19:02.312+0000] {taskinstance.py:1851} ERROR - Task failed with exception
Traceback (most recent call last):
  File "/home/airflow/.local/lib/python3.7/site-packages/airflow/operators/python.py", line 175, in execute
    return_value = self.execute_callable()
  File "/home/airflow/.local/lib/python3.7/site-packages/airflow/operators/python.py", line 193, in execute_callable
    return self.python_callable(*self.op_args, **self.op_kwargs)
  File "/opt/airflow/dags/packages/predicting_process.py", line 17, in predictor
    layer_activations = nn.forward(X_test)
  File "/opt/airflow/dags/packages/source/net.py", line 177, in forward
    activations.append(el.forward(input))
  File "/opt/airflow/dags/packages/source/net.py", line 74, in forward
    return np.dot(input, self.weights) + self.biases
  File "<__array_function__ internals>", line 6, in dot
ValueError: shapes (315,15) and (14,200) not aligned: 15 (dim 1) != 14 (dim 0)
[2022-11-26T15:19:02.329+0000] {taskinstance.py:1406} INFO - Marking task as FAILED. dag_id=data_predict_dag, task_id=data_predict, execution_date=20221125T000000, start_date=20221126T151901, end_date=20221126T151902
[2022-11-26T15:19:02.343+0000] {standard_task_runner.py:105} ERROR - Failed to execute job 4 for task data_predict (shapes (315,15) and (14,200) not aligned: 15 (dim 1) != 14 (dim 0); 78)
[2022-11-26T15:19:02.398+0000] {local_task_job.py:159} INFO - Task exited with return code 1
[2022-11-26T15:19:02.424+0000] {taskinstance.py:2623} INFO - 0 downstream tasks scheduled from follow-on schedule check
