[2022-11-29T03:57:22.096+0000] {taskinstance.py:1165} INFO - Dependencies all met for <TaskInstance: data_predict_dag.data_predict scheduled__2022-11-28T00:00:00+00:00 [queued]>
[2022-11-29T03:57:22.111+0000] {taskinstance.py:1165} INFO - Dependencies all met for <TaskInstance: data_predict_dag.data_predict scheduled__2022-11-28T00:00:00+00:00 [queued]>
[2022-11-29T03:57:22.111+0000] {taskinstance.py:1362} INFO - 
--------------------------------------------------------------------------------
[2022-11-29T03:57:22.112+0000] {taskinstance.py:1363} INFO - Starting attempt 1 of 1
[2022-11-29T03:57:22.112+0000] {taskinstance.py:1364} INFO - 
--------------------------------------------------------------------------------
[2022-11-29T03:57:22.137+0000] {taskinstance.py:1383} INFO - Executing <Task(PythonOperator): data_predict> on 2022-11-28 00:00:00+00:00
[2022-11-29T03:57:22.150+0000] {standard_task_runner.py:55} INFO - Started process 67 to run task
[2022-11-29T03:57:22.161+0000] {standard_task_runner.py:82} INFO - Running: ['***', 'tasks', 'run', 'data_predict_dag', 'data_predict', 'scheduled__2022-11-28T00:00:00+00:00', '--job-id', '20', '--raw', '--subdir', 'DAGS_FOLDER/dag_predict_proccess.py', '--cfg-path', '/tmp/tmpeyzqfa7j']
[2022-11-29T03:57:22.171+0000] {standard_task_runner.py:83} INFO - Job 20: Subtask data_predict
[2022-11-29T03:57:22.330+0000] {task_command.py:376} INFO - Running <TaskInstance: data_predict_dag.data_predict scheduled__2022-11-28T00:00:00+00:00 [running]> on host 18e45f209dfb
[2022-11-29T03:57:22.445+0000] {taskinstance.py:1592} INFO - Exporting the following env vars:
AIRFLOW_CTX_DAG_OWNER=***
AIRFLOW_CTX_DAG_ID=data_predict_dag
AIRFLOW_CTX_TASK_ID=data_predict
AIRFLOW_CTX_EXECUTION_DATE=2022-11-28T00:00:00+00:00
AIRFLOW_CTX_TRY_NUMBER=1
AIRFLOW_CTX_DAG_RUN_ID=scheduled__2022-11-28T00:00:00+00:00
[2022-11-29T03:57:22.608+0000] {taskinstance.py:1851} ERROR - Task failed with exception
Traceback (most recent call last):
  File "/home/airflow/.local/lib/python3.7/site-packages/airflow/operators/python.py", line 175, in execute
    return_value = self.execute_callable()
  File "/home/airflow/.local/lib/python3.7/site-packages/airflow/operators/python.py", line 193, in execute_callable
    return self.python_callable(*self.op_args, **self.op_kwargs)
  File "/opt/airflow/dags/packages/predicting_process.py", line 17, in predictor
    layer_activations = nn.forward(X_test)
  File "/opt/airflow/dags/packages/source/net.py", line 177, in forward
    activations.append(el.forward(input))
  File "/opt/airflow/dags/packages/source/net.py", line 74, in forward
    return np.dot(input, self.weights) + self.biases
  File "<__array_function__ internals>", line 6, in dot
ValueError: shapes (333,17) and (15,200) not aligned: 17 (dim 1) != 15 (dim 0)
[2022-11-29T03:57:22.645+0000] {taskinstance.py:1406} INFO - Marking task as FAILED. dag_id=data_predict_dag, task_id=data_predict, execution_date=20221128T000000, start_date=20221129T035722, end_date=20221129T035722
[2022-11-29T03:57:22.686+0000] {standard_task_runner.py:105} ERROR - Failed to execute job 20 for task data_predict (shapes (333,17) and (15,200) not aligned: 17 (dim 1) != 15 (dim 0); 67)
[2022-11-29T03:57:22.737+0000] {local_task_job.py:159} INFO - Task exited with return code 1
[2022-11-29T03:57:22.768+0000] {taskinstance.py:2623} INFO - 0 downstream tasks scheduled from follow-on schedule check
