[2022-11-26T15:04:05.021+0000] {taskinstance.py:1165} INFO - Dependencies all met for <TaskInstance: data_predict_dag.data_predict manual__2022-11-26T15:04:02.201621+00:00 [queued]>
[2022-11-26T15:04:05.027+0000] {taskinstance.py:1165} INFO - Dependencies all met for <TaskInstance: data_predict_dag.data_predict manual__2022-11-26T15:04:02.201621+00:00 [queued]>
[2022-11-26T15:04:05.027+0000] {taskinstance.py:1362} INFO - 
--------------------------------------------------------------------------------
[2022-11-26T15:04:05.028+0000] {taskinstance.py:1363} INFO - Starting attempt 1 of 1
[2022-11-26T15:04:05.028+0000] {taskinstance.py:1364} INFO - 
--------------------------------------------------------------------------------
[2022-11-26T15:04:05.036+0000] {taskinstance.py:1383} INFO - Executing <Task(PythonOperator): data_predict> on 2022-11-26 15:04:02.201621+00:00
[2022-11-26T15:04:05.042+0000] {standard_task_runner.py:55} INFO - Started process 20273 to run task
[2022-11-26T15:04:05.047+0000] {standard_task_runner.py:82} INFO - Running: ['***', 'tasks', 'run', 'data_predict_dag', 'data_predict', 'manual__2022-11-26T15:04:02.201621+00:00', '--job-id', '497', '--raw', '--subdir', 'DAGS_FOLDER/dag_predict_proccess.py', '--cfg-path', '/tmp/tmp9d2frqj7']
[2022-11-26T15:04:05.048+0000] {standard_task_runner.py:83} INFO - Job 497: Subtask data_predict
[2022-11-26T15:04:05.112+0000] {task_command.py:376} INFO - Running <TaskInstance: data_predict_dag.data_predict manual__2022-11-26T15:04:02.201621+00:00 [running]> on host 3151441c8efc
[2022-11-26T15:04:05.158+0000] {taskinstance.py:1592} INFO - Exporting the following env vars:
AIRFLOW_CTX_DAG_OWNER=***
AIRFLOW_CTX_DAG_ID=data_predict_dag
AIRFLOW_CTX_TASK_ID=data_predict
AIRFLOW_CTX_EXECUTION_DATE=2022-11-26T15:04:02.201621+00:00
AIRFLOW_CTX_TRY_NUMBER=1
AIRFLOW_CTX_DAG_RUN_ID=manual__2022-11-26T15:04:02.201621+00:00
[2022-11-26T15:04:05.170+0000] {taskinstance.py:1851} ERROR - Task failed with exception
Traceback (most recent call last):
  File "/home/airflow/.local/lib/python3.7/site-packages/airflow/operators/python.py", line 175, in execute
    return_value = self.execute_callable()
  File "/home/airflow/.local/lib/python3.7/site-packages/airflow/operators/python.py", line 193, in execute_callable
    return self.python_callable(*self.op_args, **self.op_kwargs)
  File "/opt/airflow/dags/packages/predicting_process.py", line 14, in predictor
    nn = NN.import_nn(conf.MODEL_DATA_PATH)
  File "/opt/airflow/dags/packages/source/net.py", line 135, in import_nn
    raise e
  File "/opt/airflow/dags/packages/source/net.py", line 122, in import_nn
    with open(filename) as f:
FileNotFoundError: [Errno 2] No such file or directory: 'data/raw/ds/model.json'
[2022-11-26T15:04:05.181+0000] {taskinstance.py:1406} INFO - Marking task as FAILED. dag_id=data_predict_dag, task_id=data_predict, execution_date=20221126T150402, start_date=20221126T150405, end_date=20221126T150405
[2022-11-26T15:04:05.187+0000] {standard_task_runner.py:105} ERROR - Failed to execute job 497 for task data_predict ([Errno 2] No such file or directory: 'data/raw/ds/model.json'; 20273)
[2022-11-26T15:04:05.220+0000] {local_task_job.py:159} INFO - Task exited with return code 1
[2022-11-26T15:04:05.233+0000] {taskinstance.py:2623} INFO - 0 downstream tasks scheduled from follow-on schedule check
