[2022-11-25T20:19:08.508+0000] {taskinstance.py:1165} INFO - Dependencies all met for <TaskInstance: gen_data_dag.data_generation scheduled__2022-11-24T00:00:00+00:00 [queued]>
[2022-11-25T20:19:08.518+0000] {taskinstance.py:1165} INFO - Dependencies all met for <TaskInstance: gen_data_dag.data_generation scheduled__2022-11-24T00:00:00+00:00 [queued]>
[2022-11-25T20:19:08.519+0000] {taskinstance.py:1362} INFO - 
--------------------------------------------------------------------------------
[2022-11-25T20:19:08.520+0000] {taskinstance.py:1363} INFO - Starting attempt 1 of 1
[2022-11-25T20:19:08.520+0000] {taskinstance.py:1364} INFO - 
--------------------------------------------------------------------------------
[2022-11-25T20:19:08.530+0000] {taskinstance.py:1383} INFO - Executing <Task(PythonOperator): data_generation> on 2022-11-24 00:00:00+00:00
[2022-11-25T20:19:08.542+0000] {standard_task_runner.py:55} INFO - Started process 689 to run task
[2022-11-25T20:19:08.551+0000] {standard_task_runner.py:82} INFO - Running: ['***', 'tasks', 'run', 'gen_data_dag', 'data_generation', 'scheduled__2022-11-24T00:00:00+00:00', '--job-id', '273', '--raw', '--subdir', 'DAGS_FOLDER/dag_generate_data.py', '--cfg-path', '/tmp/tmp85x9l_8a']
[2022-11-25T20:19:08.554+0000] {standard_task_runner.py:83} INFO - Job 273: Subtask data_generation
[2022-11-25T20:19:08.626+0000] {task_command.py:376} INFO - Running <TaskInstance: gen_data_dag.data_generation scheduled__2022-11-24T00:00:00+00:00 [running]> on host 1b5d66f3d148
[2022-11-25T20:19:08.702+0000] {taskinstance.py:1592} INFO - Exporting the following env vars:
AIRFLOW_CTX_DAG_OWNER=***
AIRFLOW_CTX_DAG_ID=gen_data_dag
AIRFLOW_CTX_TASK_ID=data_generation
AIRFLOW_CTX_EXECUTION_DATE=2022-11-24T00:00:00+00:00
AIRFLOW_CTX_TRY_NUMBER=1
AIRFLOW_CTX_DAG_RUN_ID=scheduled__2022-11-24T00:00:00+00:00
[2022-11-25T20:19:08.717+0000] {taskinstance.py:1851} ERROR - Task failed with exception
Traceback (most recent call last):
  File "/home/airflow/.local/lib/python3.7/site-packages/airflow/operators/python.py", line 175, in execute
    return_value = self.execute_callable()
  File "/home/airflow/.local/lib/python3.7/site-packages/airflow/operators/python.py", line 193, in execute_callable
    return self.python_callable(*self.op_args, **self.op_kwargs)
  File "/opt/airflow/dags/packages/gen2_data.py", line 6, in gen_data
    df = pd.read_csv('../../../data/data.csv')
  File "/home/airflow/.local/lib/python3.7/site-packages/pandas/util/_decorators.py", line 311, in wrapper
    return func(*args, **kwargs)
  File "/home/airflow/.local/lib/python3.7/site-packages/pandas/io/parsers/readers.py", line 586, in read_csv
    return _read(filepath_or_buffer, kwds)
  File "/home/airflow/.local/lib/python3.7/site-packages/pandas/io/parsers/readers.py", line 482, in _read
    parser = TextFileReader(filepath_or_buffer, **kwds)
  File "/home/airflow/.local/lib/python3.7/site-packages/pandas/io/parsers/readers.py", line 811, in __init__
    self._engine = self._make_engine(self.engine)
  File "/home/airflow/.local/lib/python3.7/site-packages/pandas/io/parsers/readers.py", line 1040, in _make_engine
    return mapping[engine](self.f, **self.options)  # type: ignore[call-arg]
  File "/home/airflow/.local/lib/python3.7/site-packages/pandas/io/parsers/c_parser_wrapper.py", line 51, in __init__
    self._open_handles(src, kwds)
  File "/home/airflow/.local/lib/python3.7/site-packages/pandas/io/parsers/base_parser.py", line 229, in _open_handles
    errors=kwds.get("encoding_errors", "strict"),
  File "/home/airflow/.local/lib/python3.7/site-packages/pandas/io/common.py", line 707, in get_handle
    newline="",
FileNotFoundError: [Errno 2] No such file or directory: '../../../data/data.csv'
[2022-11-25T20:19:08.729+0000] {taskinstance.py:1406} INFO - Marking task as FAILED. dag_id=gen_data_dag, task_id=data_generation, execution_date=20221124T000000, start_date=20221125T201908, end_date=20221125T201908
[2022-11-25T20:19:08.747+0000] {standard_task_runner.py:105} ERROR - Failed to execute job 273 for task data_generation ([Errno 2] No such file or directory: '../../../data/data.csv'; 689)
[2022-11-25T20:19:08.803+0000] {local_task_job.py:159} INFO - Task exited with return code 1
[2022-11-25T20:19:08.830+0000] {taskinstance.py:2623} INFO - 0 downstream tasks scheduled from follow-on schedule check
