[2022-11-26T07:54:54.104+0000] {taskinstance.py:1165} INFO - Dependencies all met for <TaskInstance: data_generator_dag.data_generation manual__2022-11-26T07:54:52.489425+00:00 [queued]>
[2022-11-26T07:54:54.110+0000] {taskinstance.py:1165} INFO - Dependencies all met for <TaskInstance: data_generator_dag.data_generation manual__2022-11-26T07:54:52.489425+00:00 [queued]>
[2022-11-26T07:54:54.111+0000] {taskinstance.py:1362} INFO - 
--------------------------------------------------------------------------------
[2022-11-26T07:54:54.111+0000] {taskinstance.py:1363} INFO - Starting attempt 1 of 1
[2022-11-26T07:54:54.111+0000] {taskinstance.py:1364} INFO - 
--------------------------------------------------------------------------------
[2022-11-26T07:54:54.119+0000] {taskinstance.py:1383} INFO - Executing <Task(PythonOperator): data_generation> on 2022-11-26 07:54:52.489425+00:00
[2022-11-26T07:54:54.126+0000] {standard_task_runner.py:55} INFO - Started process 439 to run task
[2022-11-26T07:54:54.130+0000] {standard_task_runner.py:82} INFO - Running: ['***', 'tasks', 'run', 'data_generator_dag', 'data_generation', 'manual__2022-11-26T07:54:52.489425+00:00', '--job-id', '455', '--raw', '--subdir', 'DAGS_FOLDER/dag_generate_data.py', '--cfg-path', '/tmp/tmp75z198zo']
[2022-11-26T07:54:54.133+0000] {standard_task_runner.py:83} INFO - Job 455: Subtask data_generation
[2022-11-26T07:54:54.191+0000] {task_command.py:376} INFO - Running <TaskInstance: data_generator_dag.data_generation manual__2022-11-26T07:54:52.489425+00:00 [running]> on host 3151441c8efc
[2022-11-26T07:54:54.239+0000] {taskinstance.py:1592} INFO - Exporting the following env vars:
AIRFLOW_CTX_DAG_OWNER=***
AIRFLOW_CTX_DAG_ID=data_generator_dag
AIRFLOW_CTX_TASK_ID=data_generation
AIRFLOW_CTX_EXECUTION_DATE=2022-11-26T07:54:52.489425+00:00
AIRFLOW_CTX_TRY_NUMBER=1
AIRFLOW_CTX_DAG_RUN_ID=manual__2022-11-26T07:54:52.489425+00:00
[2022-11-26T07:54:54.242+0000] {taskinstance.py:1851} ERROR - Task failed with exception
Traceback (most recent call last):
  File "/home/airflow/.local/lib/python3.7/site-packages/airflow/operators/python.py", line 175, in execute
    return_value = self.execute_callable()
  File "/home/airflow/.local/lib/python3.7/site-packages/airflow/operators/python.py", line 193, in execute_callable
    return self.python_callable(*self.op_args, **self.op_kwargs)
  File "/opt/airflow/dags/packages/gen2_data.py", line 8, in gen_data
    df = pd.read_csv('data/raw/ds/data.csv')
  File "/home/airflow/.local/lib/python3.7/site-packages/pandas/util/_decorators.py", line 311, in wrapper
    return func(*args, **kwargs)
  File "/home/airflow/.local/lib/python3.7/site-packages/pandas/io/parsers/readers.py", line 586, in read_csv
    return _read(filepath_or_buffer, kwds)
  File "/home/airflow/.local/lib/python3.7/site-packages/pandas/io/parsers/readers.py", line 482, in _read
    parser = TextFileReader(filepath_or_buffer, **kwds)
  File "/home/airflow/.local/lib/python3.7/site-packages/pandas/io/parsers/readers.py", line 811, in __init__
    self._engine = self._make_engine(self.engine)
  File "/home/airflow/.local/lib/python3.7/site-packages/pandas/io/parsers/readers.py", line 1040, in _make_engine
    return mapping[engine](self.f, **self.options)  # type: ignore[call-arg]
  File "/home/airflow/.local/lib/python3.7/site-packages/pandas/io/parsers/c_parser_wrapper.py", line 51, in __init__
    self._open_handles(src, kwds)
  File "/home/airflow/.local/lib/python3.7/site-packages/pandas/io/parsers/base_parser.py", line 229, in _open_handles
    errors=kwds.get("encoding_errors", "strict"),
  File "/home/airflow/.local/lib/python3.7/site-packages/pandas/io/common.py", line 707, in get_handle
    newline="",
FileNotFoundError: [Errno 2] No such file or directory: 'data/raw/ds/data.csv'
[2022-11-26T07:54:54.250+0000] {taskinstance.py:1406} INFO - Marking task as FAILED. dag_id=data_generator_dag, task_id=data_generation, execution_date=20221126T075452, start_date=20221126T075454, end_date=20221126T075454
[2022-11-26T07:54:54.261+0000] {standard_task_runner.py:105} ERROR - Failed to execute job 455 for task data_generation ([Errno 2] No such file or directory: 'data/raw/ds/data.csv'; 439)
[2022-11-26T07:54:54.305+0000] {local_task_job.py:159} INFO - Task exited with return code 1
[2022-11-26T07:54:54.319+0000] {taskinstance.py:2623} INFO - 0 downstream tasks scheduled from follow-on schedule check
